Workbook

Sheet Avaliacao
A1: Problem | B1: Student | C1: Attempt | D1: Status_Original | E1: Codigo_Aluno | F1: Gemini_is_correct | G1: Gemini_linha_erro | H1: Gemini_tipo_erro | I1: Gemini_feedback_formativo | J1: Gemini_dica_acao | K1: Gold_tipo_erro | L1: Gold_linha_erro | M1: Gold_descricao_correcao | N1: Diagnostico_Correto | O1: Nao_Revela_Solucao_1a5 | P1: Foco_Unico_Erro_1a5 | Q1: Qualidade_Socratica_1a5 | R1: Clareza_1a5 | S1: Tom_Motivacional_1a5 | T1: Comentarios
A2: 1132 | B2: 1 | C2: 1 | D2: Runtime error | E2: #include <stdio.h> X, Y = map(int, input().split()) soma = 0 for c in range(X, Y) if c % 13 != 0: soma += c print(soma) | F2: FALSE | G2: 6 | H2: Sintaxe | I2: O interpretador Python encontrou um problema de estrutura na linha 6 e não conseguiu iniciar a execução do seu programa. | J2: Observe a estrutura do seu 'if' na linha 7 e compare com o seu 'for' na linha 6. Qual sinal visual o Python exige no final dessas linhas de comando para indicar o início de um novo bloco? | K2: Sintaxe | L2: 6 | M2: [RASCUNHO] Falta ':' no final do for (SyntaxError) | N2: =IF(AND(H2<>"",K2<>""),IF(H2=K2,1,0),"")
A3: 1132 | B3: 1 | C3: 2 | D3: Runtime error | E3: #include <stdio.h> X, Y = map(int, input().split()) soma = 0 for c in range(X, Y + 1) if c % 13 != 0: soma += c print(soma) | F3: FALSE | G3: 6 | H3: Sintaxe | I3: O seu código está bem estruturado, mas o Python interrompeu a leitura assim que tentou criar a sua estrutura de repetição. | J3: Compare a escrita da linha 6 (o `for`) com a linha 7 (o `if`). Qual sinal estrutural você utilizou no final da linha 7 para indicar o início do bloco que não está presente na linha 6? | K3: Sintaxe | L3: 6 | M3: [RASCUNHO] Ainda falta ':' no for -- regressao do erro de sintaxe nao corrigida | N3: =IF(AND(H3<>"",K3<>""),IF(H3=K3,1,0),"")
A4: 1132 | B4: 1 | C4: 3 | D4: Wrong answer (100%) | E4: #include <stdio.h> X = int(input()) Y = int(input()) soma = 0 for c in range(X, Y+1): if c % 13 != 0: soma += c print(soma) | F4: FALSE | G4: 7 | H4: Lógica | I4: Seu código funciona bem quando o primeiro número digitado é menor que o segundo. Porém, o programa não produz o resultado correto dependendo da ordem das entradas. | J4: O que acontece com a execução do laço `for` se o usuário digitar X = 20 e Y = 10? Simule esse caso passo a passo. | K4: Lógica | L4: 7 | M4: [RASCUNHO] Nao trata o caso X > Y (falta swap dos valores antes do loop) | N4: =IF(AND(H4<>"",K4<>""),IF(H4=K4,1,0),"")
A5: 1132 | B5: 1 | C5: 4 | D5: Runtime error | E5: #include <stdio.h> X, Y= map(int. input()) soma = 0 for c in range(X, Y+1): if c % 13 != 0: soma += c print(soma) | F5: FALSE | G5: 3 | H5: Sintaxe | I5: O interpretador Python não conseguiu entender a instrução na linha onde você recebe os dados de entrada. | J5: Examine a pontuação usada dentro da função `map` na linha 3. Qual caractere o Python utiliza para separar os diferentes argumentos de uma função? | K5: Sintaxe | L5: 3 | M5: [RASCUNHO] 'int. input()' com ponto em vez de virgula -- erro de digitacao (SyntaxError) | N5: =IF(AND(H5<>"",K5<>""),IF(H5=K5,1,0),"")
A6: 1132 | B6: 1 | C6: 5 | D6: Runtime error | E6: #include <stdio.h> X, Y= map(int. input().split()) soma = 0 for c in range(X, Y+1): if c % 13 != 0: soma += c print(soma) | F6: FALSE | G6: 3 | H6: Sintaxe | I6: Olá! Notei que o Python não conseguiu sequer começar a rodar seu código por causa de um pequeno detalhe de sintaxe na leitura dos dados. | J6: Olhe bem para a linha 3 na chamada da função `map(...)`: qual é o caractere que a linguagem Python exige para separar diferentes argumentos dentro de uma função? | K6: Sintaxe | L6: 3 | M6: [RASCUNHO] Mesmo erro de digitacao 'int.' ainda nao corrigido | N6: =IF(AND(H6<>"",K6<>""),IF(H6=K6,1,0),"")
A7: 1132 | B7: 1 | C7: 6 | D7: Runtime error | E7: #include <stdio.h> X, Y= map(int, input().split()) soma = 0 for c in range(X, Y+1): if c % 13 != 0: soma += c print(soma) | F7: FALSE | G7: 6 | H7: Lógica | I7: Seu código executa perfeitamente em termos de sintaxe, mas em certas combinações de entrada o laço de repetição não se comporta como o esperado. | J7: Simule o seu código no papel ou execute-o fornecendo os valores X = 20 e Y = 10. Qual é a saída obtida e por que o laço se comporta dessa forma? | K7: Execução | L7: 3 | M7: [RASCUNHO] input().split() le os dois valores da mesma linha, mas o formato de entrada tem X e Y em linhas separadas (erro ao desempacotar) | N7: =IF(AND(H7<>"",K7<>""),IF(H7=K7,1,0),"")
A8: 1132 | B8: 1 | C8: 7 | D8: Wrong answer (100%) | E8: #include <stdio.h> X = int(input()) Y= int(input()) soma = 0 for c in range(X, Y+1): if c % 13 != 0: soma += c print(soma) | F8: FALSE | G8: 7 | H8: Lógica | I8: Seu código funciona muito bem quando o primeiro número lido é menor que o segundo. No entanto, o enunciado não garante a ordem das entradas X e Y. | J8: O que acontece com o seu laço de repetição se o usuário digitar X = 20 e Y = 10? Tente simular a execução nesse cenário. | K8: Lógica | L8: 7 | M8: [RASCUNHO] Nao trata o caso X > Y (mesmo problema da tentativa 3) | N8: =IF(AND(H8<>"",K8<>""),IF(H8=K8,1,0),"")
A9: 1132 | B9: 1 | C9: 8 | D9: Accepted | E9: #include <stdio.h> X = int(input()) Y = int(input()) if X > Y: X, Y = Y, X soma = 0 for c in range(X, Y+1): if c % 13 != 0: soma += c print(soma) | F9: TRUE | I9: Excelente trabalho! Seu código está muito bem estruturado, lida corretamente com a ordem dos números e resolve o problema perfeitamente em Python 3. | J9: Como um desafio de aprimoramento: você saberia reescrever esse laço de repetição em uma única linha usando a função `sum()` junto com uma expressão geradora? | K9: Nenhum (código correto) | M9: [RASCUNHO] Accepted | N9: =IF(AND(H9<>"",K9<>""),IF(H9=K9,1,0),"")
A10: 1132 | B10: 2 | C10: 1 | D10: Runtime error | E10: x = int(input()) y = int(input()) naoDivisiveisPor13 = [] for numero in rage(x, y + 1): if numero % 13 != 0: naoDivisiveisPor13.append(numero) soma = sum(naoDivisiveisPor13) print('{}'.format(soma)) | F10: FALSE | G10: 6 | H10: Execução | I10: Olá! Seu código tem uma excelente estrutura, mas o Python não conseguiu executar a linha 6 e parou antes mesmo de entrar no laço. | J10: Dê uma olhada bem atenta no nome da função utilizada na linha 6 para criar a sequência de números. Essa palavra foi digitada exatamente como o Python a conhece? | K10: Execução | L10: 6 | M10: [RASCUNHO] 'rage' deveria ser 'range' (NameError) | N10: =IF(AND(H10<>"",K10<>""),IF(H10=K10,1,0),"")
A11: 1132 | B11: 2 | C11: 2 | D11: Wrong answer (100%) | E11: x = int(input()) y = int(input()) naoDivisiveisPor13 = [] for numero in range(x, y + 1): if numero % 13 != 0: naoDivisiveisPor13.append(numero) soma = sum(naoDivisiveisPor13) print('{}'.format(soma)) | F11: FALSE | G11: 6 | H11: Lógica | I11: Seu código está muito organizado e funciona perfeitamente quando o primeiro número digitado é menor que o segundo. No entanto, há um cenário com certas entradas em que o laço de repetição não se comporta como esperado. | J11: Tente simular seu código no papel (ou rodar um teste) assumindo os valores X = 20 e Y = 10. O que acontece com a instrução `range(x, y + 1)` nesse caso? | K11: Lógica | L11: 6 | M11: [RASCUNHO] Nao trata o caso x > y (falta swap dos valores) | N11: =IF(AND(H11<>"",K11<>""),IF(H11=K11,1,0),"")
A12: 1132 | B12: 2 | C12: 3 | D12: Wrong answer (100%) | E12: x = int(input()) y = int(input()) naoDivisiveisPor13 = [] for numero in range(x, y + 1): if numero % 13 != 0: naoDivisiveisPor13.append(numero) soma = sum(naoDivisiveisPor13) print(soma) | K12: Lógica | L12: 6 | M12: [RASCUNHO] Mesmo problema: nao trata x > y | N12: =IF(AND(H12<>"",K12<>""),IF(H12=K12,1,0),"")
A13: 1132 | B13: 2 | C13: 4 | D13: Accepted | E13: x = int(input()) y = int(input()) if x > y: x, y = y, x soma = 0 for numero in range(x, y + 1): if numero % 13 != 0: soma += numero print(soma) | F13: TRUE | I13: Excelente trabalho! Seu código está super organizado, trata corretamente o intervalo mesmo se os números forem digitados fora de ordem e faz o cálculo exatamente como solicitado. | J13: Como desafio para expandir seu conhecimento: você conseguiria resolver esse mesmo problema usando a função sum() combinada com uma list comprehension? | K13: Nenhum (código correto) | M13: [RASCUNHO] Accepted | N13: =IF(AND(H13<>"",K13<>""),IF(H13=K13,1,0),"")
A14: 1132 | B14: 3 | C14: 1 | D14: Runtime error | E14: X = int(input()) Y = int(input()) def naom13(X, Y): if X > Y: X, Y = Y, X soma = 0 for c in range(X, Y + 1): if c % 13 != 0: soma += c return soma resultado = naom13(X, Y) print(f'{resultado}') | F14: TRUE | I14: Parabéns! Seu código funcionou perfeitamente e atendeu a todos os requisitos do problema, tratando inclusive o caso em que o primeiro número é maior que o segundo. | J14: Para ir além: você consegue pensar em uma forma de garantir que o menor número seja o início do range usando funções embutidas do Python como min() e max(), sem precisar do 'if'? | K14: Nenhum (código correto) | M14: [RASCUNHO] Unico diff para a versao aceita e trocar f-string por .format() | N14: =IF(AND(H14<>"",K14<>""),IF(H14=K14,1,0),"") | T14: [RASCUNHO] CASO AMBIGUO: f-string e sintaxe Python 3 valida; a diferenca sugere incompatibilidade do juiz com uma versao antiga do Python, nao um erro real detectavel na leitura do codigo. Considere revisar/excluir esta linha da metrica de acuracia. [RASCUNHO] CASO AMBIGUO: f-string e sintaxe Python 3 valida; a diferenca sugere incompatibilidade do juiz com uma versao antiga do Python, nao um erro real detectavel na leitura do codigo. Considere revisar/excluir esta linha da metrica de acuracia.
A15: 1132 | B15: 3 | C15: 2 | D15: Accepted | E15: X = int(input()) Y = int(input()) def naom13(X, Y): if X > Y: X, Y = Y, X soma = 0 for c in range(X, Y + 1): if c % 13 != 0: soma += c return soma resultado = naom13(X, Y) print('{}'.format(resultado)) | F15: TRUE | I15: Excelente trabalho! O seu código está muito bem estruturado, lida corretamente com a ordem das variáveis X e Y, e calcula a soma dos não múltiplos de 13 perfeitamente. | J15: Como desafio extra de reflexão: você saberia dizer se é possível resolver esse mesmo problema de forma matemática sem utilizar o laço de repetição 'for'? | K15: Nenhum (código correto) | M15: [RASCUNHO] Accepted | N15: =IF(AND(H15<>"",K15<>""),IF(H15=K15,1,0),"")
A16: 1153 | B16: 1 | C16: 1 | D16: Accepted | E16: N = int(input()) if 0 < N < 13: valorNovo = 1 for c in range(1, N + 1): valorNovo *= c print(valorNovo) else: print("O valor de N deve estar no intervalo 0 < N < 13.") | F16: FALSE | G16: 3 | H16: Lógica | I16: Seu algoritmo calcula o fatorial corretamente para números inteiros positivos, mas deixa de atender a um caso limite importante da definição do fatorial. | J16: Qual deve ser o resultado do fatorial quando N = 0? O que o seu código imprime se você digitar 0 como entrada? | K16: Nenhum (código correto) | M16: [RASCUNHO] Accepted | N16: =IF(AND(H16<>"",K16<>""),IF(H16=K16,1,0),"")
A17: 1153 | B17: 2 | C17: 1 | D17: Wrong answer (100%) | E17: n = int(input()) if 0 < n < 13: resultadoFatorial = 1 for i in range(1, n + 1): resultadoFatorial *= 1 print(resultadoFatorial) | F17: FALSE | G17: 7 | H17: Lógica | I17: Seu programa executa, mas o cálculo final do fatorial não está acumulando a multiplicação dos números corretamente. | J17: Simule seu código no papel para N = 4: a cada passo do laço 'for', qual é o valor da variável 'i' e quanto vale 'resultadoFatorial' após a multiplicação? | K17: Lógica | L17: 7 | M17: [RASCUNHO] 'resultadoFatorial *= 1' deveria ser '*= i' -- nunca calcula o fatorial de fato | N17: =IF(AND(H17<>"",K17<>""),IF(H17=K17,1,0),"")
A18: 1153 | B18: 2 | C18: 2 | D18: Runtime error | E18: n = int(input()) if 0 < n < 13: resultadoFatorial = 1 while n > 1 resultadoFatorial *= n n -= 1 print(resultadoFatorial) | F18: FALSE | G18: 6 | H18: Sintaxe | I18: Olá! Analisei o seu código e notei que o interpretador do Python não consegue iniciar a execução do programa devido a uma falha de estrutura na linha 6. | J18: Compare o final do comando na linha 3 com o final do comando na linha 6. O que a linha 3 possui no fim do seu elemento de controle que está ausente na linha 6? | K18: Sintaxe | L18: 6 | M18: [RASCUNHO] Falta ':' no final do while (SyntaxError) | N18: =IF(AND(H18<>"",K18<>""),IF(H18=K18,1,0),"")
A19: 1153 | B19: 2 | C19: 3 | D19: Accepted | E19: N = int(input()) if 0 < N < 13: resultado_fatorial = 1 for i in range(2, N + 1): resultado_fatorial *= i print(resultado_fatorial) else: print("Por favor, insira um valor válido para N.") | F19: FALSE | G19: 3 | H19: Lógica | I19: Sua estrutura de repetição e o cálculo estão muito bem construídos! Porém, existe um caso de teste na matemática que sua validação inicial está desconsiderando. | J19: Qual é o valor matemático de 0! (fatorial de zero)? O que o seu programa imprime se o valor de entrada for N = 0? | K19: Nenhum (código correto) | M19: [RASCUNHO] Accepted | N19: =IF(AND(H19<>"",K19<>""),IF(H19=K19,1,0),"")
A20: 1153 | B20: 3 | C20: 1 | D20: Accepted | E20: N = int(input()) fatorial = 1 for c in range(N, 0, -1): fatorial *= c print('{}'.format(fatorial)) | F20: TRUE | I20: Parabéns! Seu código está correto, limpo e resolve o problema perfeitamente. | J20: Sua lógica com o laço `for` decrementando funcionou muito bem. Como desafio extra de aprendizado: como você reescreveria esse mesmo código usando um laço `while`? | K20: Nenhum (código correto) | M20: [RASCUNHO] Accepted | N20: =IF(AND(H20<>"",K20<>""),IF(H20=K20,1,0),"")
A21: 1828 | B21: 1 | C21: 1 | D21: Runtime error | E21: # -*- coding: utf-8 -*- T = int(input("Digite o número de casos de teste: ")) if T >= 1 and T <= 100: for c in range(1, T+1): escolha_sheldon, escolha_raj = map(str,input().split()) if escolha_sheldon == escolha_raj: print("Caso #{}: De novo!" .format(c)) elif (escolha_sheldon == "tesoura" and (escolha_raj == "papel" or escolha_raj == "lagarto")) or \ (escolha_sheldon == "papel" and (escolha_raj == "pedra" or escolha_raj == "Spock")) or \ (escolha_sheldon == "pedra" and (escolha_raj == "lagarto" or escolha_raj == "tesoura")) or \ (escolha_sheldon == "lagarto" and (escolha_raj == "Spock" or escolha_raj == "papel")) or \ (escolha_sheldon == "Spock" and (escolha_raj == "tesoura" or escolha_raj == "pedra")): print("Caso #{}: Bazinga!" .format(c) else: print("Caso #{}: Raj trapaceou!" .format(c)) | F21: FALSE | G21: 16 | H21: Sintaxe | I21: O Python encontrou um problema de estrutura no seu código e não conseguiu interpretar a instrução antes de chegar na cláusula 'else'. Isso impede que o programa seja executado. | J21: Examine atentamente a linha do 'print' dentro do bloco 'elif'. Conte quantos parênteses você abriu e quantos você fechou nessa instrução. Todos os parênteses abertos foram devidamente fechados? | K21: Sintaxe | L21: 16 | M21: [RASCUNHO] Parenteses desbalanceados no print (falta um ')') | N21: =IF(AND(H21<>"",K21<>""),IF(H21=K21,1,0),"")
A22: 1828 | B22: 1 | C22: 2 | D22: Wrong answer (5%) | E22: # -*- coding: utf-8 -*- T = int(input("Digite o número de casos de teste: ")) if T >= 1 and T <= 100: for c in range(1, T+1): escolha_sheldon, escolha_raj = map(str,input().split()) if escolha_sheldon == escolha_raj: print("Caso #{}: De novo!" .format(c)) elif (escolha_sheldon == "tesoura" and (escolha_raj == "papel" or escolha_raj == "lagarto")) or \ (escolha_sheldon == "papel" and (escolha_raj == "pedra" or escolha_raj == "Spock")) or \ (escolha_sheldon == "pedra" and (escolha_raj == "lagarto" or escolha_raj == "tesoura")) or \ (escolha_sheldon == "lagarto" and (escolha_raj == "Spock" or escolha_raj == "papel")) or \ (escolha_sheldon == "Spock" and (escolha_raj == "tesoura" or escolha_raj == "pedra")): print("Caso #{}: Bazinga!" .format(c)) else: print("Caso #{}: Raj trapaceou!" .format(c)) | F22: FALSE | G22: 3 | H22: Lógica | I22: Seu código está muito bem estruturado e a lógica do jogo faz sentido! No entanto, logo na leitura da primeira entrada, o programa envia um texto para a tela que pode fazer um corretor automático considerar a resposta incorreta. | J22: O que acontece com a saída do seu programa quando a função `input("Digite o número...")` é executada em um sistema de correção automática que compara caractere por caractere? | K22: Lógica | L22: 3 | M22: [RASCUNHO] O texto do prompt dentro de input() e impresso na saida, incompatibilizando com o gabarito esperado | N22: =IF(AND(H22<>"",K22<>""),IF(H22=K22,1,0),"")
A23: 1828 | B23: 1 | C23: 3 | D23: Accepted | E23: # -*- coding: utf-8 -*- T = int(input()) if T >= 1 and T <= 100: for c in range(1, T+1): escolha_sheldon, escolha_raj = map(str,input().split()) if escolha_sheldon == escolha_raj: print("Caso #{}: De novo!" .format(c)) elif (escolha_sheldon == "tesoura" and (escolha_raj == "papel" or escolha_raj == "lagarto")) or \ (escolha_sheldon == "papel" and (escolha_raj == "pedra" or escolha_raj == "Spock")) or \ (escolha_sheldon == "pedra" and (escolha_raj == "lagarto" or escolha_raj == "tesoura")) or \ (escolha_sheldon == "lagarto" and (escolha_raj == "Spock" or escolha_raj == "papel")) or \ (escolha_sheldon == "Spock" and (escolha_raj == "tesoura" or escolha_raj == "pedra")): print("Caso #{}: Bazinga!" .format(c)) else: print("Caso #{}: Raj trapaceou!" .format(c)) | F23: FALSE | G23: 12 | H23: Lógica | I23: Sua estrutura lógica para resolver as regras do jogo está excelente! Contudo, em Python, a comparação de textos é sensível a letras maiúsculas e minúsculas, o que faz seu programa errar em casos específicos. | J23: O que acontece se você rodar o seu código digitando a entrada '1' e depois 'spock papel'? Qual saída seu programa gera em comparação com a saída esperada? | K23: Nenhum (código correto) | M23: [RASCUNHO] Accepted | N23: =IF(AND(H23<>"",K23<>""),IF(H23=K23,1,0),"")
A24: 1828 | B24: 2 | C24: 1 | D24: Runtime error | E24: t = int(input()) if t <= 100: for caso in range(1, t + 1): escolha_sheldon, escolha_raj = input().split() if ( (escolha_sheldon == "tesoura" and escolha_raj == "papel") or (escolha_sheldon == "papel" and escolha_raj == "pedra") or (escolha_sheldon == "pedra" and escolha_raj == "lagarto") or (escolha_sheldon == "lagarto" and escolha_raj == "Spock") or (escolha_sheldon == "Spock" and escolha_raj == "tesoura") or (escolha_sheldon == "tesoura" and escolha_raj == "lagarto") or (escolha_sheldon == "lagarto" and escolha_raj == "papel") or (escolha_sheldon == "papel" and escolha_raj == "Spock") or (escolha_sheldon == "Spock" and escolha_raj == "pedra") or (escolha_sheldon == "pedra" and escolha_raj == "tesoura") ): resultado = "Bazinga!" elif escolha_sheldon == escolha_raj: resultado = "De novo!" else: resultado = "Raj trapaceou!" print('Caso #{}: {}'.format(caso, resultado)) | F24: FALSE | G24: 7 | H24: Sintaxe | I24: O Python é muito rigoroso com a organização visual do código. O interpretador não conseguiu executar o programa porque encontrou uma inconsistência no alinhamento das instruções dentro do seu bloco de repetição. | J24: Compare o início da linha onde você faz a leitura das variáveis (linha 5) com o início da linha onde começa o comando 'if' (linha 7). A quantidade de espaços antes da primeira letra é exatamente a mesma nas duas linhas? | K24: Sintaxe | L24: 7 | M24: [RASCUNHO] Indentacao inconsistente do bloco if (IndentationError) | N24: =IF(AND(H24<>"",K24<>""),IF(H24=K24,1,0),"")
A25: 1828 | B25: 2 | C25: 2 | D25: Wrong answer (100%) | E25: t = int(input()) if t <= 100: for caso in range(1, t + 1): escolha_sheldon, escolha_raj = input().split() if ( (escolha_sheldon == "tesoura" and escolha_raj == "papel") or (escolha_sheldon == "papel" and escolha_raj == "pedra") or (escolha_sheldon == "pedra" and escolha_raj == "lagarto") or (escolha_sheldon == "lagarto" and escolha_raj == "Spock") or (escolha_sheldon == "Spock" and escolha_raj == "tesoura") or (escolha_sheldon == "tesoura" and escolha_raj == "lagarto") or (escolha_sheldon == "lagarto" and escolha_raj == "papel") or (escolha_sheldon == "papel" and escolha_raj == "Spock") or (escolha_sheldon == "Spock" and escolha_raj == "pedra") or (escolha_sheldon == "pedra" and escolha_raj == "tesoura") ): resultado = "Bazinga!" elif escolha_sheldon == escolha_raj: resultado = "De novo!" else: resultado = "Raj trapaceou!" print('Caso #{}: {}'.format(caso, resultado)) | K25: Lógica | L25: 7 | M25: [RASCUNHO] Bloco if/print desindentado ficou fora do for -- so processa o ultimo caso | N25: =IF(AND(H25<>"",K25<>""),IF(H25=K25,1,0),"")
A26: 1828 | B26: 2 | C26: 3 | D26: Accepted | E26: t = int(input()) if t <= 100: for caso in range(1, t + 1): escolha_sheldon, escolha_raj = input().split() if ( (escolha_sheldon == "tesoura" and escolha_raj == "papel") or (escolha_sheldon == "papel" and escolha_raj == "pedra") or (escolha_sheldon == "pedra" and escolha_raj == "lagarto") or (escolha_sheldon == "lagarto" and escolha_raj == "Spock") or (escolha_sheldon == "Spock" and escolha_raj == "tesoura") or (escolha_sheldon == "tesoura" and escolha_raj == "lagarto") or (escolha_sheldon == "lagarto" and escolha_raj == "papel") or (escolha_sheldon == "papel" and escolha_raj == "Spock") or (escolha_sheldon == "Spock" and escolha_raj == "pedra") or (escolha_sheldon == "pedra" and escolha_raj == "tesoura") ): resultado = "Bazinga!" elif escolha_sheldon == escolha_raj: resultado = "De novo!" else: resultado = "Raj trapaceou!" print('Caso #{}: {}'.format(caso, resultado)) | K26: Nenhum (código correto) | M26: [RASCUNHO] Accepted | N26: =IF(AND(H26<>"",K26<>""),IF(H26=K26,1,0),"")
A27: 1828 | B27: 3 | C27: 1 | D27: Accepted | E27: def vence(sheldon, rajesh): regras = { 'tesoura': ['papel', 'lagarto'], 'papel': ['pedra', 'Spock'], 'pedra': ['lagarto', 'tesoura'], 'lagarto': ['Spock', 'papel'], 'Spock': ['tesoura', 'pedra'] } if sheldon == rajesh: return 'De novo!' elif rajesh in regras[sheldon]: return 'Bazinga!' else: return 'Raj trapaceou!' T = int(input()) for caso in range(1, T+1): sheldon, rajesh = input().split() resultado = vence(sheldon, rajesh) print('Caso #{}: {}'.format(caso, resultado)) | K27: Nenhum (código correto) | M27: [RASCUNHO] Accepted | N27: =IF(AND(H27<>"",K27<>""),IF(H27=K27,1,0),"")
A28: 1873 | B28: 1 | C28: 1 | D28: Runtime error | E28: # -*- coding: utf-8 -*- C = int(input()) for c in range(1, C+1): sheldon, rajesh = map(str, input().split()) if sheldon == rajesh: print('empate') elif (sheldon == 'tesoura' and (rajesh == 'papel' or rajesh == 'lagarto')) or \ (sheldon == 'papel' and (rajesh == 'pedra' or rajesh == 'spock')) or \ (sheldon == 'pedra' and (rajesh == 'lagarto' or rajesh == 'tesoura')) or \ (sheldon == 'lagarto' and (rajesh == 'spock' or rajesh == 'papel')) or \ (sheldon == 'spock' and (rajesh == 'tesoura' or rajesh == 'pedra')) print('sheldon') else: print('rajesh') | K28: Sintaxe | L28: 13 | M28: [RASCUNHO] Falta ':' no final da condicao elif | N28: =IF(AND(H28<>"",K28<>""),IF(H28=K28,1,0),"")
A29: 1873 | B29: 1 | C29: 2 | D29: Wrong answer (25%) | E29: # -*- coding: utf-8 -*- C = int(input()) for c in range(1, C+1): sheldon, rajesh = map(str, input().split()) if sheldon == rajesh: print('empate') elif (sheldon == 'tesoura' and (rajesh == 'papel' or rajesh == 'lagarto')) or \ (sheldon == 'papel' and (rajesh == 'pedra' or rajesh == 'spock')) or \ (sheldon == 'pedra' and (rajesh == 'lagarto' or rajesh == 'tesoura')) or \ (sheldon == 'lagarto' and (rajesh == 'spock' or rajesh == 'papel')) or \ (sheldon == 'spock' and (rajesh == 'tesoura' or rajesh == 'pedra')): print('sheldon') else: print('rajesh') | K29: Lógica | L29: 6 | M29: [RASCUNHO] Ordem de leitura trocada: le 'sheldon, rajesh' mas o enunciado pede rajesh antes -- inverte o vencedor | N29: =IF(AND(H29<>"",K29<>""),IF(H29=K29,1,0),"")
A30: 1873 | B30: 1 | C30: 3 | D30: Wrong answer (25%) | E30: # -*- coding: utf-8 -*- C = int(input()) for c in range(1, C+1): sheldon, rajesh = map(str, input().split()) if sheldon == rajesh: print('empate') elif (sheldon == 'tesoura' and (rajesh == 'papel' or rajesh == 'lagarto')) or \ (sheldon == 'papel' and (rajesh == 'pedra' or rajesh == 'spock')) or \ (sheldon == 'pedra' and (rajesh == 'lagarto' or rajesh == 'tesoura')) or \ (sheldon == 'lagarto' and (rajesh == 'spock' or rajesh == 'papel')) or \ (sheldon == 'spock' and (rajesh == 'tesoura' or rajesh == 'pedra')): print('sheldon') elif (rajesh == 'tesoura' and (sheldon == 'papel' or sheldon == 'lagarto')) or \ (rajesh == 'papel' and (sheldon == 'pedra' or sheldon == 'spock')) or \ (rajesh == 'pedra' and (sheldon == 'lagarto' or sheldon == 'tesoura')) or \ (rajesh == 'lagarto' and (sheldon == 'spock' or sheldon == 'papel')) or \ (rajesh == 'spock' and (sheldon == 'tesoura' or sheldon == 'pedra')): print('sheldon') | K30: Lógica | L30: 20 | M30: [RASCUNHO] No segundo elif (quando rajesh vence), o codigo imprime 'sheldon' em vez de 'rajesh' (copia-e-cola) | N30: =IF(AND(H30<>"",K30<>""),IF(H30=K30,1,0),"")
A31: 1873 | B31: 1 | C31: 4 | D31: Wrong answer (25%) | E31: # -*- coding: utf-8 -*- C = int(input()) for c in range(1, C+1): sheldon, rajesh = map(str, input().split()) if sheldon == rajesh: print('empate') elif (sheldon == 'tesoura' and (rajesh == 'papel' or rajesh == 'lagarto')) or \ (sheldon == 'papel' and (rajesh == 'pedra' or rajesh == 'spock')) or \ (sheldon == 'pedra' and (rajesh == 'lagarto' or rajesh == 'tesoura')) or \ (sheldon == 'lagarto' and (rajesh == 'spock' or rajesh == 'papel')) or \ (sheldon == 'spock' and (rajesh == 'tesoura' or rajesh == 'pedra')): print('sheldon') elif (rajesh == 'tesoura' and (sheldon == 'papel' or sheldon == 'lagarto')) or \ (rajesh == 'papel' and (sheldon == 'pedra' or sheldon == 'spock')) or \ (rajesh == 'pedra' and (sheldon == 'lagarto' or sheldon == 'tesoura')) or \ (rajesh == 'lagarto' and (sheldon == 'spock' or sheldon == 'papel')) or \ (rajesh == 'spock' and (sheldon == 'tesoura' or sheldon == 'pedra')): print('rajesh') | K31: Lógica | L31: 6 | M31: [RASCUNHO] Ainda nao corrigiu a ordem de leitura -- deveria ser (rajesh, sheldon) | N31: =IF(AND(H31<>"",K31<>""),IF(H31=K31,1,0),"")
A32: 1873 | B32: 1 | C32: 5 | D32: Runtime error | E32: # -*- coding: utf-8 -*- C = int(input()) for c in range(C): rajesh = str(input()) sheldon = str(input()) if sheldon == rajesh: print('empate') elif ( (sheldon == 'tesoura' and (rajesh == 'papel' or rajesh == 'lagarto')) or (sheldon == 'papel' and (rajesh == 'pedra' or rajesh == 'spock')) or (sheldon == 'pedra' and (rajesh == 'lagarto' or rajesh == 'tesoura')) or (sheldon == 'lagarto' and (rajesh == 'spock' or rajesh == 'papel')) or (sheldon == 'spock' and (rajesh == 'tesoura' or rajesh == 'pedra')) ): print('sheldon') else: print('rajesh') | K32: Execução | L32: 6 | M32: [RASCUNHO] Usa duas chamadas de input() separadas em vez de split() -- desalinha as entradas seguintes | N32: =IF(AND(H32<>"",K32<>""),IF(H32=K32,1,0),"")
A33: 1873 | B33: 1 | C33: 6 | D33: Runtime error | E33: # -*- coding: utf-8 -*- C = int(input()) for c in range(C): rajesh, sheldon = map(str, (input().split()) if sheldon == rajesh: print('empate') elif ( (sheldon == 'tesoura' and (rajesh == 'papel' or rajesh == 'lagarto')) or (sheldon == 'papel' and (rajesh == 'pedra' or rajesh == 'spock')) or (sheldon == 'pedra' and (rajesh == 'lagarto' or rajesh == 'tesoura')) or (sheldon == 'lagarto' and (rajesh == 'spock' or rajesh == 'papel')) or (sheldon == 'spock' and (rajesh == 'tesoura' or rajesh == 'pedra')) ): print('sheldon') else: print('rajesh') | K33: Sintaxe | L33: 6 | M33: [RASCUNHO] Parenteses desbalanceados em map() (falta um ')') | N33: =IF(AND(H33<>"",K33<>""),IF(H33=K33,1,0),"")
A34: 1873 | B34: 1 | C34: 7 | D34: Runtime error | E34: # -*- coding: utf-8 -*- C = int(input()) for c in range(C): rajesh, sheldon = map(str, (input().split()) if sheldon == rajesh: print('empate') elif ( (sheldon == 'tesoura' and (rajesh == 'papel' or rajesh == 'lagarto')) or (sheldon == 'papel' and (rajesh == 'pedra' or rajesh == 'spock')) or (sheldon == 'pedra' and (rajesh == 'lagarto' or rajesh == 'tesoura')) or (sheldon == 'lagarto' and (rajesh == 'spock' or rajesh == 'papel')) or (sheldon == 'spock' and (rajesh == 'tesoura' or rajesh == 'pedra')) ): print('sheldon') else: print('rajesh') | K34: Sintaxe | L34: 6 | M34: [RASCUNHO] Mesmo erro de parenteses desbalanceados em map() | N34: =IF(AND(H34<>"",K34<>""),IF(H34=K34,1,0),"")
A35: 1873 | B35: 1 | C35: 8 | D35: Accepted | E35: # -*- coding: utf-8 -*- C = int(input()) for c in range(C): rajesh, sheldon = map(str, input().split()) if sheldon == rajesh: print('empate') elif ( (sheldon == 'tesoura' and (rajesh == 'papel' or rajesh == 'lagarto')) or (sheldon == 'papel' and (rajesh == 'pedra' or rajesh == 'spock')) or (sheldon == 'pedra' and (rajesh == 'lagarto' or rajesh == 'tesoura')) or (sheldon == 'lagarto' and (rajesh == 'spock' or rajesh == 'papel')) or (sheldon == 'spock' and (rajesh == 'tesoura' or rajesh == 'pedra')) ): print('sheldon') else: print('rajesh') | K35: Nenhum (código correto) | M35: [RASCUNHO] Accepted | N35: =IF(AND(H35<>"",K35<>""),IF(H35=K35,1,0),"")
A36: 1873 | B36: 2 | C36: 1 | D36: Runtime error | E36: C = int(input()) regras = { "tesoura": ["papel", "lagarto"], "papel": ["pedra", "Spock"], "pedra": ["lagarto", "tesoura"], "lagarto": ["Spock", "papel"], "Spock": ["tesoura", "pedra"] } de determinar_vencedor(escolha_raj, escolha_sheldon): if escolha_raj == escolha_sheldon: return "empate" elif escolha_sheldon in regras[escolha_raj]: return "rajesh" else: return "sheldon" for caso in range(C): escolha_raj, escolha_sheldon = input().split() resultado = determinar_vencedor(escolha_raj, escolha_sheldon) print(resultado) | K36: Sintaxe | L36: 11 | M36: [RASCUNHO] 'de' deveria ser 'def' -- erro de digitacao na definicao da funcao | N36: =IF(AND(H36<>"",K36<>""),IF(H36=K36,1,0),"")
A37: 1873 | B37: 2 | C37: 2 | D37: Runtime error | E37: C = int(input()) regras = { "tesoura": ["papel", "lagarto"], "papel": ["pedra", "Spock"], "pedra": ["lagarto", "tesoura"], "lagarto": ["Spock", "papel"], "Spock": ["tesoura", "pedra"] } def determinar_vencedor(escolha_raj, escolha_sheldon): if escolha_raj == escolha_sheldon: return "empate" elif escolha_sheldon in regras[escolha_raj]: return "rajesh" else: return "sheldon" for caso in range(C): escolha_raj, escolha_sheldon = input().split() resultado = determinar_vencedor(escolha_raj, escolha_sheldon) prit(resultado) | K37: Execução | L37: 24 | M37: [RASCUNHO] 'prit' deveria ser 'print' (NameError) | N37: =IF(AND(H37<>"",K37<>""),IF(H37=K37,1,0),"")
A38: 1873 | B38: 2 | C38: 3 | D38: Wrong answer (10%) | E38: C = int(input()) regras = { "tesoura": ["papel", "lagarto"], "papel": ["pedra", "Spock"], "pedra": ["lagarto", "tesoura"], "lagarto": ["Spock", "papel"], "Spock": ["tesoura", "pedra"] } def determinar_vencedor(escolha_raj, escolha_sheldon): if escolha_raj == escolha_sheldon: return "empate" elif escolha_sheldon in regras[escolha_raj]: return "rajesh" else: return "sheldon" for caso in range(C): escolha_raj, escolha_sheldon = input().split() resultado = determinar_vencedor(escolha_raj, escolha_sheldon) print(resultado) | K38: Lógica | L38: 5 | M38: [RASCUNHO] Inconsistencia de maiusculas/minusculas em 'Spock' no dicionario nao bate com a entrada em minusculas | N38: =IF(AND(H38<>"",K38<>""),IF(H38=K38,1,0),"")
A39: 1873 | B39: 2 | C39: 4 | D39: Wrong answer (10%) | E39: C = int(input()) regras = { "tesoura": ["papel", "lagarto"], "papel": ["pedra", "Spock"], "pedra": ["lagarto", "tesoura"], "lagarto": ["Spock", "papel"], "Spock": ["tesoura", "pedra"] } def determinar_vencedor(escolha_raj, escolha_sheldon): if escolha_raj == escolha_sheldon: return "empate" elif escolha_sheldon in regras[escolha_raj]: return "rajesh" else: return "sheldon" for caso in range(C): escolha_raj, escolha_sheldon = input().lower().split() resultado = determinar_vencedor(escolha_raj, escolha_sheldon) print(resultado) | K39: Lógica | L39: 5 | M39: [RASCUNHO] Mesmo problema de capitalizacao de 'Spock', mesmo apos normalizar a entrada com .lower() | N39: =IF(AND(H39<>"",K39<>""),IF(H39=K39,1,0),"")
A40: 1873 | B40: 2 | C40: 5 | D40: Wrong answer (10%) | E40: C = int(input()) regras = { "tesoura": ["papel", "lagarto"], "papel": ["pedra", "Spock"], "pedra": ["lagarto", "tesoura"], "lagarto": ["Spock", "papel"], "Spock": ["tesoura", "pedra"] } def determinar_vencedor(escolha_raj, escolha_sheldon): if escolha_raj == escolha_sheldon: return "empate" elif escolha_sheldon in regras[escolha_raj]: return "rajesh" else: return "sheldon" for caso in range(C): escolha_raj, escolha_sheldon = input().split() resultado = determinar_vencedor(escolha_raj, escolha_sheldon) print(resultado) | K40: Lógica | L40: 5 | M40: [RASCUNHO] Mesmo problema de capitalizacao de 'Spock' (regrediu a normalizacao) | N40: =IF(AND(H40<>"",K40<>""),IF(H40=K40,1,0),"")
...

Sheet Rubrica
A1: Coluna | B1: O que significa e como preencher
A2: Gemini_* | B2: Preenchidas automaticamente pelo script avaliar_lote.py, a partir do JSON retornado pelo modelo.
A3: Gold_tipo_erro / Gold_linha_erro | B3: Padrão-ouro. Compare o código desta tentativa com a PRÓXIMA tentativa do mesmo aluno/problema: a diferença entre elas geralmente revela o que foi corrigido. Se o Status_Original já é 'Accepted', use 'Nenhum (código correto)'. Preenchido manualmente (rápido: normalmente é só olhar o diff).
A4: Gold_descricao_correcao | B4: Uma frase curta descrevendo a correção real (ex.: 'faltavam dois-pontos no for').
A5: Diagnostico_Correto | B5: Fórmula automática: 1 se Gemini_tipo_erro bate com Gold_tipo_erro, 0 caso contrário.
A6: Nao_Revela_Solucao (1-5) | B6: 5 = não entrega a solução em nenhuma forma (nem em texto). 3 = insinua fortemente o que fazer. 1 = entrega a correção pronta (viola a regra 1 do prompt).
A7: Foco_Unico_Erro (1-5) | B7: 5 = trata explicitamente de um único erro por vez, como pedido no prompt. 1 = mistura vários erros na mesma resposta.
A8: Qualidade_Socratica (1-5) | B8: 5 = a dica_acao é de fato uma pergunta guiada/caso de teste que leva o aluno a descobrir sozinho. 1 = é uma instrução direta disfarçada de pergunta.
A9: Clareza (1-5) | B9: 5 = linguagem clara e adequada a um iniciante. 1 = confuso ou usa jargão excessivo.
A10: Tom_Motivacional (1-5) | B10: 5 = encoraja o aluno. 1 = tom seco ou desmotivador.
A11: Comentarios | B11: Qualquer observação qualitativa relevante (ex.: alucinação, erro de linha, resposta vaga).

Sheet Resumo
A1: Total de casos avaliados | B1: =COUNTA(Avaliacao!A2:A44)
A2: Casos com diagnóstico preenchido | B2: =COUNT(Avaliacao!N2:N44)
A3: % Diagnóstico correto (tipo de erro) | B3: =IFERROR(AVERAGE(Avaliacao!N2:N44),"")
A5: Média - Não revela solução | B5: =IFERROR(AVERAGE(Avaliacao!O2:O44),"")
A6: Média - Foco em um único erro | B6: =IFERROR(AVERAGE(Avaliacao!P2:P44),"")
A7: Média - Qualidade socrática | B7: =IFERROR(AVERAGE(Avaliacao!Q2:Q44),"")
A8: Média - Clareza | B8: =IFERROR(AVERAGE(Avaliacao!R2:R44),"")
A9: Média - Tom motivacional | B9: =IFERROR(AVERAGE(Avaliacao!S2:S44),"")
A11: Por problema
A13: Problema | B13: % Diagnóstico correto | C13: Média Qualidade Socrática
A14: 1132 | B14: =IFERROR(AVERAGEIF(Avaliacao!A2:A44,1132,Avaliacao!N2:N44),"") | C14: =IFERROR(AVERAGEIF(Avaliacao!A2:A44,1132,Avaliacao!Q2:Q44),"")
A15: 1153 | B15: =IFERROR(AVERAGEIF(Avaliacao!A2:A44,1153,Avaliacao!N2:N44),"") | C15: =IFERROR(AVERAGEIF(Avaliacao!A2:A44,1153,Avaliacao!Q2:Q44),"")
A16: 1828 | B16: =IFERROR(AVERAGEIF(Avaliacao!A2:A44,1828,Avaliacao!N2:N44),"") | C16: =IFERROR(AVERAGEIF(Avaliacao!A2:A44,1828,Avaliacao!Q2:Q44),"")
A17: 1873 | B17: =IFERROR(AVERAGEIF(Avaliacao!A2:A44,1873,Avaliacao!N2:N44),"") | C17: =IFERROR(AVERAGEIF(Avaliacao!A2:A44,1873,Avaliacao!Q2:Q44),"")
